2014-06-20 10:30:47,082 - netcdf - ERROR - ERROR: lock file already exists

2014-06-20 10:31:10,180 - netcdf - ERROR - Database Error: tipo <class 'psycopg2.ProgrammingError'>; código: 42601 
error de sintaxis en o cerca de «)»
LINE 1: ...time_shipcargo_daily WHERE date='2014-06-01'::date LIMIT 2);
                                                                     ^
Traceback (most recent call last):
  File "netcdf.py", line 78, in <module>
    cursor_con.execute(sentencia)
ProgrammingError: error de sintaxis en o cerca de «)»
LINE 1: ...time_shipcargo_daily WHERE date='2014-06-01'::date LIMIT 2);
                                                                     ^

2014-06-20 10:38:34,506 - netcdf - ERROR - Database Error: tipo <class 'psycopg2.ProgrammingError'>; código: 42601 
error de sintaxis en o cerca de «)»
LINE 1: ...time_shipcargo_daily WHERE date='2014-06-01'::date LIMIT 2);
                                                                     ^
Traceback (most recent call last):
  File "netcdf.py", line 78, in <module>
    cursor_con.execute(sentencia)
ProgrammingError: error de sintaxis en o cerca de «)»
LINE 1: ...time_shipcargo_daily WHERE date='2014-06-01'::date LIMIT 2);
                                                                     ^

2014-06-20 10:48:48,546 - netcdf - ERROR - ERROR: lock file already exists

2014-06-20 10:53:55,385 - netcdf - ERROR - ERROR: lock file already exists

2014-06-20 10:54:01,081 - netcdf - ERROR - Database Error: tipo <class 'psycopg2.ProgrammingError'>; código: 42601 
error de sintaxis en o cerca de «)»
LINE 1: ...time_shipcargo_daily WHERE date='2014-06-01'::date LIMIT 2);
                                                                     ^
Traceback (most recent call last):
  File "netcdf.py", line 94, in <module>
    cursor_con.execute(sentencia)
ProgrammingError: error de sintaxis en o cerca de «)»
LINE 1: ...time_shipcargo_daily WHERE date='2014-06-01'::date LIMIT 2);
                                                                     ^

2014-06-21 18:19:11,451 - netcdf - ERROR - Database Error: tipo <class 'psycopg2.ProgrammingError'>; código: 42601 
error de sintaxis en o cerca de «)»
LINE 1: ...time_shipcargo_daily WHERE date='2014-06-01'::date LIMIT 2);
                                                                     ^
Traceback (most recent call last):
  File "netcdf.py", line 94, in <module>
    cursor_con.execute(sentencia)
ProgrammingError: error de sintaxis en o cerca de «)»
LINE 1: ...time_shipcargo_daily WHERE date='2014-06-01'::date LIMIT 2);
                                                                     ^

2014-06-21 18:20:02,798 - netcdf - ERROR - Database Error: tipo <class 'psycopg2.ProgrammingError'>; código: 42601 
error de sintaxis en o cerca de «)»
LINE 1: ...time_shipcargo_daily WHERE date='2014-06-01'::date LIMIT 2);
                                                                     ^
Traceback (most recent call last):
  File "netcdf.py", line 96, in <module>
    cursor_con.execute(sentencia)
ProgrammingError: error de sintaxis en o cerca de «)»
LINE 1: ...time_shipcargo_daily WHERE date='2014-06-01'::date LIMIT 2);
                                                                     ^

2014-06-21 18:21:01,024 - netcdf - ERROR - Database Error: tipo <class 'psycopg2.ProgrammingError'>; código: 42601 
error de sintaxis en o cerca de «)»
LINE 1: ...time_shipcargo_daily WHERE date='2014-06-01'::date LIMIT 2);
                                                                     ^
Traceback (most recent call last):
  File "netcdf.py", line 96, in <module>
    cursor_con.execute(sentencia)
ProgrammingError: error de sintaxis en o cerca de «)»
LINE 1: ...time_shipcargo_daily WHERE date='2014-06-01'::date LIMIT 2);
                                                                     ^

2014-06-21 18:24:36,710 - netcdf - ERROR - Database Error: tipo <class 'psycopg2.ProgrammingError'>; código: 42P01 
falta una entrada para la tabla «marine_traffic» en la cláusula FROM
LINE 1: SELECT marine_traffic.marine_traffic.grid_time_shipcargo_dai...
               ^
Traceback (most recent call last):
  File "netcdf.py", line 96, in <module>
    cursor_con.execute(sentencia)
ProgrammingError: falta una entrada para la tabla «marine_traffic» en la cláusula FROM
LINE 1: SELECT marine_traffic.marine_traffic.grid_time_shipcargo_dai...
               ^

2014-06-21 18:25:29,986 - netcdf - ERROR - Database Error: tipo <class 'psycopg2.NotSupportedError'>; código: 0A000 
no están implementadas las referencias entre bases de datos: «marine_traffic.marine_traffic.grid_time_shipcargo_daily»
LINE 1: SELECT * FROM marine_traffic.marine_traffic.grid_time_shipca...
                      ^
Traceback (most recent call last):
  File "netcdf.py", line 96, in <module>
    cursor_con.execute(sentencia)
NotSupportedError: no están implementadas las referencias entre bases de datos: «marine_traffic.marine_traffic.grid_time_shipcargo_daily»
LINE 1: SELECT * FROM marine_traffic.marine_traffic.grid_time_shipca...
                      ^

2014-06-21 18:30:17,755 - netcdf - ERROR - ERROR: lock file already exists

2014-06-21 18:40:35,096 - netcdf - ERROR - ERROR: lock file already exists

2014-06-21 18:55:15,297 - netcdf - ERROR - ERROR: lock file already exists

2014-06-21 19:12:55,419 - netcdf - ERROR - ERROR: lock file already exists

2014-06-21 19:16:14,076 - netcdf - ERROR - ERROR: lock file already exists

2014-06-21 19:23:49,310 - netcdf - ERROR - Excepcion: tipo <type 'exceptions.NameError'>; 
name 'np' is not defined
Traceback (most recent call last):
  File "netcdf.py", line 97, in <module>
    AA = np.asarray(cursor_con.fetchall())
NameError: name 'np' is not defined
2014-06-21 19:24:48,410 - netcdf - ERROR - Excepcion: tipo <type 'exceptions.NameError'>; 
name 'asarray' is not defined
Traceback (most recent call last):
  File "netcdf.py", line 97, in <module>
    AA = asarray(cursor_con.fetchall())
NameError: name 'asarray' is not defined
2014-06-21 19:26:01,295 - netcdf - ERROR - Excepcion: tipo <type 'exceptions.NameError'>; 
name 'np' is not defined
Traceback (most recent call last):
  File "netcdf.py", line 116, in <module>
    A = np.asarray(results)
NameError: name 'np' is not defined
2014-06-21 19:27:11,161 - netcdf - ERROR - Excepcion: tipo <type 'exceptions.NameError'>; 
name 'np' is not defined
Traceback (most recent call last):
  File "netcdf.py", line 116, in <module>
    A = np.asarray(results)
NameError: name 'np' is not defined
2014-06-21 19:28:00,311 - netcdf - ERROR - Excepcion: tipo <type 'exceptions.ValueError'>; 
field named f0 not found.
Traceback (most recent call last):
  File "netcdf.py", line 118, in <module>
    results_c1 = AA['f0']
ValueError: field named f0 not found.
2014-06-23 18:54:52,503 - netcdf - ERROR - Excepcion: tipo <type 'exceptions.TypeError'>; 
float() argument must be a string or a number
Traceback (most recent call last):
  File "netcdf.py", line 97, in <module>
    result = numpy.fromiter((tuple (row) for row in cursor_con), dtype=[('date',float), ('ship_cargo',int),('time_sec',float)])
TypeError: float() argument must be a string or a number
2014-06-23 18:58:32,934 - netcdf - ERROR - Excepcion: tipo <type 'exceptions.TypeError'>; 
data type not understood
Traceback (most recent call last):
  File "netcdf.py", line 98, in <module>
    result = numpy.fromiter((tuple (row) for row in cursor_con), dtype=('f8','f8','f8'))
TypeError: data type not understood
2014-06-23 19:00:13,628 - netcdf - ERROR - Excepcion: tipo <type 'exceptions.TypeError'>; 
data type not understood
Traceback (most recent call last):
  File "netcdf.py", line 98, in <module>
    result = numpy.fromiter((tuple (row) for row in cursor_con), dtype=(numpy.float,numpy.float,numpy.float))
TypeError: data type not understood
2014-06-23 19:01:10,849 - netcdf - ERROR - Excepcion: tipo <type 'exceptions.TypeError'>; 
data type not understood
Traceback (most recent call last):
  File "netcdf.py", line 98, in <module>
    result = numpy.fromiter((tuple (row) for row in cursor_con), dtype=(float,float,float))
TypeError: data type not understood
2014-06-23 19:01:48,183 - netcdf - ERROR - Excepcion: tipo <type 'exceptions.TypeError'>; 
Required argument 'dtype' (pos 2) not found
Traceback (most recent call last):
  File "netcdf.py", line 98, in <module>
    result = numpy.fromiter((tuple (row) for row in cursor_con))
TypeError: Required argument 'dtype' (pos 2) not found
2014-06-23 19:12:01,671 - netcdf - ERROR - Excepcion: tipo <type 'exceptions.TypeError'>; 
float() argument must be a string or a number
Traceback (most recent call last):
  File "netcdf.py", line 98, in <module>
    result = numpy.fromiter((tuple (row) for row in cursor_con), dtype='f8,f8,f8')
TypeError: float() argument must be a string or a number
2014-06-24 06:52:28,954 - netcdf - ERROR - Excepcion: tipo <type 'exceptions.TypeError'>; 
float() argument must be a string or a number
Traceback (most recent call last):
  File "netcdf.py", line 98, in <module>
    result = numpy.fromiter((tuple (row) for row in cursor_con), dtype='f8,f8,f8')
TypeError: float() argument must be a string or a number
2014-06-24 06:53:57,538 - netcdf - ERROR - Excepcion: tipo <type 'exceptions.TypeError'>; 
float() argument must be a string or a number
Traceback (most recent call last):
  File "netcdf.py", line 99, in <module>
    result = numpy.fromiter((tuple (row) for row in cursor_con), dtype='f8,f8,f8')
TypeError: float() argument must be a string or a number
2014-06-24 06:55:28,104 - netcdf - ERROR - Excepcion: tipo <type 'exceptions.TypeError'>; 
long() argument must be a string or a number, not 'datetime.date'
Traceback (most recent call last):
  File "netcdf.py", line 106, in <module>
    arrayi = numpy.fromiter(resultis_as_list, dtype=numpy.int32)
TypeError: long() argument must be a string or a number, not 'datetime.date'
2014-06-24 07:02:46,709 - netcdf - ERROR - Excepcion: tipo <type 'exceptions.TypeError'>; 
data type not understood
Traceback (most recent call last):
  File "netcdf.py", line 106, in <module>
    arrayi = numpy.fromiter(resultis_as_list, dtype=(numpy.long, numpy.int, numpy.float))
TypeError: data type not understood
2014-06-24 07:09:25,314 - netcdf - ERROR - Excepcion: tipo <type 'exceptions.TypeError'>; 
data type not understood
Traceback (most recent call last):
  File "netcdf.py", line 106, in <module>
    arrayi = numpy.fromiter(resultis_as_list, dtype=(numpy.float, numpy.float, numpy.float))
TypeError: data type not understood
2014-06-24 07:12:57,201 - netcdf - ERROR - Excepcion: tipo <type 'exceptions.NameError'>; 
name 'float64' is not defined
Traceback (most recent call last):
  File "netcdf.py", line 106, in <module>
    arrayi = numpy.fromiter(resultis_as_list, dtype=(float64, float64, float64))
NameError: name 'float64' is not defined
2014-06-24 07:15:36,334 - netcdf - ERROR - Excepcion: tipo <type 'exceptions.TypeError'>; 
data type not understood
Traceback (most recent call last):
  File "netcdf.py", line 106, in <module>
    arrayi = numpy.fromiter(resultis_as_list, dtype=(numpy.float64, numpy.float64, numpy.float64))
TypeError: data type not understood
2014-06-24 07:16:28,473 - netcdf - ERROR - Excepcion: tipo <type 'exceptions.TypeError'>; 
data type not understood
Traceback (most recent call last):
  File "netcdf.py", line 106, in <module>
    arrayi = numpy.fromiter(resultis_as_list, dtype='numpy.float64, numpy.float64, numpy.float64')
TypeError: data type not understood
2014-06-24 07:19:36,414 - netcdf - ERROR - Excepcion: tipo <type 'exceptions.TypeError'>; 
expected a readable buffer object
Traceback (most recent call last):
  File "netcdf.py", line 106, in <module>
    arrayi = numpy.fromiter(resultis_as_list, dtype="f8,f8,f8")
TypeError: expected a readable buffer object
2014-06-24 07:21:19,919 - netcdf - ERROR - Excepcion: tipo <type 'exceptions.TypeError'>; 
expected a readable buffer object
Traceback (most recent call last):
  File "netcdf.py", line 106, in <module>
    arrayi = numpy.fromiter(resultis_as_list, dtype="f8,f8,f8")
TypeError: expected a readable buffer object
2014-06-24 07:49:23,401 - netcdf - ERROR - Excepcion: tipo <type 'exceptions.NameError'>; 
name 'result' is not defined
Traceback (most recent call last):
  File "netcdf.py", line 111, in <module>
    print "result: {}".format(result)
NameError: name 'result' is not defined
2014-06-24 07:51:12,706 - netcdf - ERROR - Excepcion: tipo <type 'exceptions.NameError'>; 
name 'result' is not defined
Traceback (most recent call last):
  File "netcdf.py", line 111, in <module>
    print "result: {}".format(result)
NameError: name 'result' is not defined
2014-06-24 07:52:54,335 - netcdf - ERROR - Excepcion: tipo <type 'exceptions.TypeError'>; 
float() argument must be a string or a number
Traceback (most recent call last):
  File "netcdf.py", line 110, in <module>
    data1 = numpy.array(data[:,0],dtype="Float64")
TypeError: float() argument must be a string or a number
2014-06-24 07:54:01,815 - netcdf - ERROR - Excepcion: tipo <type 'exceptions.TypeError'>; 
float() argument must be a string or a number
Traceback (most recent call last):
  File "netcdf.py", line 110, in <module>
    data1 = numpy.array(data[:,0],dtype='f8')
TypeError: float() argument must be a string or a number
2014-06-24 07:55:03,281 - netcdf - ERROR - Excepcion: tipo <type 'exceptions.TypeError'>; 
float() argument must be a string or a number
Traceback (most recent call last):
  File "netcdf.py", line 110, in <module>
    data1 = numpy.array(data[0],dtype='f8')
TypeError: float() argument must be a string or a number
2014-06-24 08:38:45,825 - netcdf - ERROR - Excepcion: tipo <type 'exceptions.TypeError'>; 
float() argument must be a string or a number
Traceback (most recent call last):
  File "netcdf.py", line 110, in <module>
    data1 = numpy.array(data[0],dtype='f8')
TypeError: float() argument must be a string or a number
2014-06-24 08:40:40,946 - netcdf - ERROR - Excepcion: tipo <type 'exceptions.TypeError'>; 
float() argument must be a string or a number
Traceback (most recent call last):
  File "netcdf.py", line 110, in <module>
    data1 = numpy.array(data[:,0],dtype='f8')
TypeError: float() argument must be a string or a number
2014-06-24 08:41:23,766 - netcdf - ERROR - Excepcion: tipo <type 'exceptions.NameError'>; 
name 'data1' is not defined
Traceback (most recent call last):
  File "netcdf.py", line 112, in <module>
    print "result: {}".format(data1)
NameError: name 'data1' is not defined
2014-06-24 08:42:25,686 - netcdf - ERROR - Excepcion: tipo <type 'exceptions.NameError'>; 
name 'result' is not defined
Traceback (most recent call last):
  File "netcdf.py", line 116, in <module>
    results_c1 = result['f0']
NameError: name 'result' is not defined
2014-06-24 08:58:28,353 - netcdf - ERROR - Excepcion: tipo <type 'exceptions.NameError'>; 
name 'result' is not defined
Traceback (most recent call last):
  File "netcdf.py", line 116, in <module>
    results_c1 = result['f0']
NameError: name 'result' is not defined
2014-06-24 09:03:03,340 - netcdf - ERROR - Excepcion: tipo <type 'exceptions.NameError'>; 
name 'cur' is not defined
Traceback (most recent call last):
  File "netcdf.py", line 100, in <module>
    data = numpy.array([tuple(row) for row in cur])
NameError: name 'cur' is not defined
2014-06-24 09:04:12,728 - netcdf - ERROR - Excepcion: tipo <type 'exceptions.AttributeError'>; 
'module' object has no attribute 'datetime64'
Traceback (most recent call last):
  File "netcdf.py", line 101, in <module>
    data_date = numpy.array(data[:,0],dtype=numpy.datetime64)
AttributeError: 'module' object has no attribute 'datetime64'
2014-06-24 09:09:02,205 - netcdf - ERROR - Excepcion: tipo <type 'exceptions.AttributeError'>; 
'module' object has no attribute 'string'
Traceback (most recent call last):
  File "netcdf.py", line 101, in <module>
    data_date = numpy.array(data[:,0],dtype=numpy.string)
AttributeError: 'module' object has no attribute 'string'
2014-06-24 09:10:08,392 - netcdf - ERROR - Excepcion: tipo <type 'exceptions.NameError'>; 
name 'string' is not defined
Traceback (most recent call last):
  File "netcdf.py", line 101, in <module>
    data_date = numpy.array(data[:,0],dtype=string)
NameError: name 'string' is not defined
2014-06-24 09:10:49,380 - netcdf - ERROR - Excepcion: tipo <type 'exceptions.NameError'>; 
name 'result' is not defined
Traceback (most recent call last):
  File "netcdf.py", line 107, in <module>
    results_c1 = result['f0']
NameError: name 'result' is not defined
2014-06-24 09:11:52,265 - netcdf - ERROR - Excepcion: tipo <type 'exceptions.NameError'>; 
name 'result' is not defined
Traceback (most recent call last):
  File "netcdf.py", line 107, in <module>
    results_c1 = result['f0']
NameError: name 'result' is not defined
2014-06-24 09:13:16,541 - netcdf - ERROR - Excepcion: tipo <type 'exceptions.NameError'>; 
name 'result' is not defined
Traceback (most recent call last):
  File "netcdf.py", line 107, in <module>
    results_c1 = result['f0']
NameError: name 'result' is not defined
2014-06-24 09:16:10,500 - netcdf - ERROR - Excepcion: tipo <type 'exceptions.TypeError'>; 
not all arguments converted during string formatting
Traceback (most recent call last):
  File "netcdf.py", line 110, in <module>
    print "Dentro del cursor: " % (cursor_cont)
TypeError: not all arguments converted during string formatting
2014-06-24 09:17:42,540 - netcdf - ERROR - Excepcion: tipo <type 'exceptions.TypeError'>; 
not all arguments converted during string formatting
Traceback (most recent call last):
  File "netcdf.py", line 110, in <module>
    print "Dentro del cursor: " % (cursor_cont)
TypeError: not all arguments converted during string formatting
2014-06-24 09:18:35,619 - netcdf - ERROR - Excepcion: tipo <type 'exceptions.TypeError'>; 
data type not understood
Traceback (most recent call last):
  File "netcdf.py", line 103, in <module>
    data_timesec = numpy.array(data[:,2],dtype='f32')
TypeError: data type not understood
2014-06-24 09:20:15,789 - netcdf - ERROR - Excepcion: tipo <type 'exceptions.TypeError'>; 
not all arguments converted during string formatting
Traceback (most recent call last):
  File "netcdf.py", line 110, in <module>
    print "Dentro del cursor: " % (cursor_cont)
TypeError: not all arguments converted during string formatting
2014-06-24 09:21:46,160 - netcdf - ERROR - Excepcion: tipo <type 'exceptions.TypeError'>; 
not all arguments converted during string formatting
Traceback (most recent call last):
  File "netcdf.py", line 110, in <module>
    print "Dentro del cursor: " % (cursor_cont)
TypeError: not all arguments converted during string formatting
2014-06-24 09:22:38,409 - netcdf - ERROR - Excepcion: tipo <type 'exceptions.TypeError'>; 
not all arguments converted during string formatting
Traceback (most recent call last):
  File "netcdf.py", line 110, in <module>
    print "Dentro del cursor: " % (cursor_cont)
TypeError: not all arguments converted during string formatting
2014-06-24 09:25:29,336 - netcdf - ERROR - Excepcion: tipo <type 'exceptions.TypeError'>; 
data type not understood
Traceback (most recent call last):
  File "netcdf.py", line 103, in <module>
    data_timesec = numpy.array(data[:,2],dtype='float256')
TypeError: data type not understood
2014-06-24 09:27:05,268 - netcdf - ERROR - Excepcion: tipo <type 'exceptions.TypeError'>; 
data type not understood
Traceback (most recent call last):
  File "netcdf.py", line 103, in <module>
    data_timesec = numpy.array(data[:,2],dtype='float256')
TypeError: data type not understood
2014-06-24 09:27:46,928 - netcdf - ERROR - Excepcion: tipo <type 'exceptions.AttributeError'>; 
'module' object has no attribute 'float256'
Traceback (most recent call last):
  File "netcdf.py", line 103, in <module>
    data_timesec = numpy.array(data[:,2],dtype=numpy.float256)
AttributeError: 'module' object has no attribute 'float256'
2014-06-24 09:28:49,998 - netcdf - ERROR - Excepcion: tipo <type 'exceptions.TypeError'>; 
data type not understood
Traceback (most recent call last):
  File "netcdf.py", line 103, in <module>
    data_timesec = numpy.array(data[:,2],dtype='f256')
TypeError: data type not understood
2014-06-24 09:30:00,375 - netcdf - ERROR - Excepcion: tipo <type 'exceptions.NameError'>; 
name 'float128' is not defined
Traceback (most recent call last):
  File "netcdf.py", line 103, in <module>
    data_timesec = numpy.array(data[:,2],dtype=float128)
NameError: name 'float128' is not defined
2014-06-24 09:30:24,591 - netcdf - ERROR - Excepcion: tipo <type 'exceptions.TypeError'>; 
not all arguments converted during string formatting
Traceback (most recent call last):
  File "netcdf.py", line 110, in <module>
    print "Dentro del cursor: " % (cursor_cont)
TypeError: not all arguments converted during string formatting
2014-06-24 09:32:56,190 - netcdf - ERROR - Excepcion: tipo <type 'exceptions.TypeError'>; 
not all arguments converted during string formatting
Traceback (most recent call last):
  File "netcdf.py", line 112, in <module>
    print "Dentro del cursor: " % (cursor_cont)
TypeError: not all arguments converted during string formatting
2014-06-24 09:36:19,245 - netcdf - ERROR - Excepcion: tipo <type 'exceptions.TypeError'>; 
not all arguments converted during string formatting
Traceback (most recent call last):
  File "netcdf.py", line 119, in <module>
    print "Dentro del cursor: " % (cursor_cont)
TypeError: not all arguments converted during string formatting
2014-06-24 09:37:48,791 - netcdf - ERROR - Excepcion: tipo <type 'exceptions.TypeError'>; 
not all arguments converted during string formatting
Traceback (most recent call last):
  File "netcdf.py", line 119, in <module>
    print "Dentro del cursor: " % (cursor_cont)
TypeError: not all arguments converted during string formatting
2014-06-24 09:50:19,349 - netcdf - ERROR - Excepcion: tipo <type 'exceptions.TypeError'>; 
not all arguments converted during string formatting
Traceback (most recent call last):
  File "netcdf.py", line 122, in <module>
    print "Dentro del cursor: " % (cursor_cont)
TypeError: not all arguments converted during string formatting
2014-06-24 09:56:14,059 - netcdf - ERROR - Excepcion: tipo <type 'exceptions.RuntimeError'>; 
NetCDF: String match to name in use
Traceback (most recent call last):
  File "netcdf.py", line 126, in <module>
    time = ncfile.createDimension('time', None); # None
  File "netCDF4.pyx", line 1549, in netCDF4.Dataset.createDimension (netCDF4.c:21457)
  File "netCDF4.pyx", line 2015, in netCDF4.Dimension.__init__ (netCDF4.c:25972)
RuntimeError: NetCDF: String match to name in use
2014-06-24 09:59:56,237 - netcdf - ERROR - Excepcion: tipo <type 'exceptions.NameError'>; 
name 'unique_lon' is not defined
Traceback (most recent call last):
  File "netcdf.py", line 128, in <module>
    ndim_lon = numpy.size(unique_lon)
NameError: name 'unique_lon' is not defined
2014-06-24 10:04:42,197 - netcdf - ERROR - Excepcion: tipo <type 'exceptions.NameError'>; 
name 'numpy_lon' is not defined
Traceback (most recent call last):
  File "netcdf.py", line 122, in <module>
    print "data_lon: {}".format(numpy_lon)
NameError: name 'numpy_lon' is not defined
2014-06-24 10:06:52,831 - netcdf - ERROR - Excepcion: tipo <type 'exceptions.RuntimeError'>; 
NetCDF: String match to name in use
Traceback (most recent call last):
  File "netcdf.py", line 132, in <module>
    time = ncfile.createDimension('time', ndim_time);
  File "netCDF4.pyx", line 1549, in netCDF4.Dataset.createDimension (netCDF4.c:21457)
  File "netCDF4.pyx", line 2015, in netCDF4.Dimension.__init__ (netCDF4.c:25972)
RuntimeError: NetCDF: String match to name in use
2014-06-24 10:49:37,540 - netcdf - ERROR - Excepcion: tipo <type 'exceptions.RuntimeError'>; 
NetCDF: String match to name in use
Traceback (most recent call last):
  File "netcdf.py", line 132, in <module>
    time = ncfile.createDimension('time', ndim_time);
  File "netCDF4.pyx", line 1549, in netCDF4.Dataset.createDimension (netCDF4.c:21457)
  File "netCDF4.pyx", line 2015, in netCDF4.Dimension.__init__ (netCDF4.c:25972)
RuntimeError: NetCDF: String match to name in use
2014-06-24 11:07:13,132 - netcdf - ERROR - Excepcion: tipo <type 'exceptions.RuntimeError'>; 
NetCDF: String match to name in use
Traceback (most recent call last):
  File "netcdf.py", line 132, in <module>
    time = ncfile.createDimension('time', ndim_time);
  File "netCDF4.pyx", line 1549, in netCDF4.Dataset.createDimension (netCDF4.c:21457)
  File "netCDF4.pyx", line 2015, in netCDF4.Dimension.__init__ (netCDF4.c:25972)
RuntimeError: NetCDF: String match to name in use
2014-06-24 11:09:39,218 - netcdf - ERROR - Excepcion: tipo <type 'exceptions.TypeError'>; 
not all arguments converted during string formatting
Traceback (most recent call last):
  File "netcdf.py", line 130, in <module>
    print "Dentro del cursor: " % (cursor_cont)
TypeError: not all arguments converted during string formatting
2014-06-24 11:20:02,644 - netcdf - ERROR - Excepcion: tipo <type 'exceptions.ValueError'>; 
invalid literal for float(): 2014-06-01
Traceback (most recent call last):
  File "netcdf.py", line 129, in <module>
    times[:] = unique_time
  File "netCDF4.pyx", line 3066, in netCDF4.Variable.__setitem__ (netCDF4.c:38763)
  File "netCDF4.pyx", line 3186, in netCDF4.Variable._put (netCDF4.c:39652)
ValueError: invalid literal for float(): 2014-06-01
2014-06-24 11:21:53,805 - netcdf - ERROR - Excepcion: tipo <type 'exceptions.TypeError'>; 
illegal primitive data type, must be one of ['i8', 'f4', 'u8', 'i1', 'U1', 'S1', 'i2', 'u1', 'i4', 'u2', 'f8', 'u4'], got |S10
Traceback (most recent call last):
  File "netcdf.py", line 121, in <module>
    times = ncfile.createVariable('time','S10',('time',))
  File "netCDF4.pyx", line 1721, in netCDF4.Dataset.createVariable (netCDF4.c:22375)
  File "netCDF4.pyx", line 2268, in netCDF4.Variable.__init__ (netCDF4.c:28060)
TypeError: illegal primitive data type, must be one of ['i8', 'f4', 'u8', 'i1', 'U1', 'S1', 'i2', 'u1', 'i4', 'u2', 'f8', 'u4'], got |S10
2014-06-24 11:26:56,949 - netcdf - ERROR - Excepcion: tipo <type 'exceptions.NameError'>; 
name 'numpu' is not defined
Traceback (most recent call last):
  File "netcdf.py", line 129, in <module>
    times[:] = numpu.asarray(unique_time)
NameError: name 'numpu' is not defined
2014-06-24 11:35:03,342 - netcdf - ERROR - Excepcion: tipo <type 'exceptions.NameError'>; 
name 'unique_long' is not defined
Traceback (most recent call last):
  File "netcdf.py", line 131, in <module>
    longitudes = numpy.asarray(unique_long)
NameError: name 'unique_long' is not defined
2014-06-24 12:10:43,985 - netcdf - ERROR - Excepcion: tipo <type 'exceptions.AttributeError'>; 
'numpy.ndarray' object has no attribute 'index'
Traceback (most recent call last):
  File "netcdf.py", line 142, in <module>
    indice_time = times.index(row[0])
AttributeError: 'numpy.ndarray' object has no attribute 'index'
2014-06-24 12:18:27,913 - netcdf - ERROR - Excepcion: tipo <type 'exceptions.TypeError'>; 
where() takes no keyword arguments
Traceback (most recent call last):
  File "netcdf.py", line 143, in <module>
    indice_time = numpy.where(times = row[0])
TypeError: where() takes no keyword arguments
2014-06-24 12:22:53,184 - netcdf - ERROR - Excepcion: tipo <type 'exceptions.AttributeError'>; 
'numpy.ndarray' object has no attribute 'index'
Traceback (most recent call last):
  File "netcdf.py", line 142, in <module>
    indice_time = unique_time.index(row[0])
AttributeError: 'numpy.ndarray' object has no attribute 'index'
2014-06-24 12:25:34,088 - netcdf - ERROR - Excepcion: tipo <type 'exceptions.AttributeError'>; 
'numpy.ndarray' object has no attribute 'index'
Traceback (most recent call last):
  File "netcdf.py", line 142, in <module>
    indice_time = unique_time.index(row[0])[0]
AttributeError: 'numpy.ndarray' object has no attribute 'index'
2014-06-24 12:26:11,619 - netcdf - ERROR - Excepcion: tipo <type 'exceptions.IndexError'>; 
tuple index out of range
Traceback (most recent call last):
  File "netcdf.py", line 143, in <module>
    indice_time = numpy.where(times == row[0])[0]
IndexError: tuple index out of range
2014-06-24 13:00:50,579 - netcdf - ERROR - Excepcion: tipo <type 'exceptions.AttributeError'>; 
'datetime.date' object has no attribute 'astype'
Traceback (most recent call last):
  File "netcdf.py", line 145, in <module>
    indice_time = numpy.where(times[0] == row_date.astype('|S10'))
AttributeError: 'datetime.date' object has no attribute 'astype'
2014-06-24 22:14:26,443 - netcdf - ERROR - Excepcion: tipo <type 'exceptions.AttributeError'>; 
'module' object has no attribute 'datetime64'
Traceback (most recent call last):
  File "netcdf.py", line 85, in <module>
    data_date = numpy.array(data[:,0],dtype=numpy.datetime64)
AttributeError: 'module' object has no attribute 'datetime64'
2014-06-24 22:15:46,067 - netcdf - ERROR - Excepcion: tipo <type 'exceptions.AttributeError'>; 
'module' object has no attribute 'datetime'
Traceback (most recent call last):
  File "netcdf.py", line 85, in <module>
    data_date = numpy.array(data[:,0],dtype=numpy.datetime)
AttributeError: 'module' object has no attribute 'datetime'
2014-06-24 22:17:00,535 - netcdf - ERROR - Excepcion: tipo <type 'exceptions.TypeError'>; 
data type not understood
Traceback (most recent call last):
  File "netcdf.py", line 85, in <module>
    data_date = numpy.array(data[:,0],dtype='datetime64')
TypeError: data type not understood
2014-06-24 22:18:20,088 - netcdf - ERROR - Excepcion: tipo <type 'exceptions.TypeError'>; 
data type not understood
Traceback (most recent call last):
  File "netcdf.py", line 85, in <module>
    data_date = numpy.array(data[:,0],dtype='datetime')
TypeError: data type not understood
2014-06-24 22:31:47,270 - netcdf - ERROR - Excepcion: tipo <type 'exceptions.TypeError'>; 
data type not understood
Traceback (most recent call last):
  File "netcdf.py", line 85, in <module>
    data_date = numpy.array(data[:,0],dtype='numpy.datetime64')
TypeError: data type not understood
2014-06-24 22:54:41,922 - netcdf - ERROR - Excepcion: tipo <type 'exceptions.NameError'>; 
name 'urllib' is not defined
Traceback (most recent call last):
  File "netcdf.py", line 149, in <module>
    indice_time = numpy.where(times == urllib.quote("'{}'".format(row_date)))
NameError: name 'urllib' is not defined
2014-06-24 23:11:04,142 - netcdf - ERROR - Excepcion: tipo <type 'exceptions.IndexError'>; 
tuple index out of range
Traceback (most recent call last):
  File "netcdf.py", line 147, in <module>
    print "TIEMPO: {} índice {}".format(row[0],indice_time[0])
IndexError: tuple index out of range
2014-06-24 23:11:33,423 - netcdf - ERROR - Excepcion: tipo <type 'exceptions.IndexError'>; 
tuple index out of range
Traceback (most recent call last):
  File "netcdf.py", line 147, in <module>
    print "TIEMPO: {} índice {}".format(row[0],indice_time[0])
IndexError: tuple index out of range
2014-06-24 23:13:38,400 - netcdf - ERROR - Excepcion: tipo <type 'exceptions.IndexError'>; 
tuple index out of range
Traceback (most recent call last):
  File "netcdf.py", line 148, in <module>
    print "TIEMPO: {} índice {}".format(row[0],indice_time[0])
IndexError: tuple index out of range
2014-06-24 23:14:48,051 - netcdf - ERROR - Excepcion: tipo <type 'exceptions.IndexError'>; 
tuple index out of range
Traceback (most recent call last):
  File "netcdf.py", line 149, in <module>
    print "TIEMPO: {} índice {}".format(row[0],indice_time[0])
IndexError: tuple index out of range
2014-06-24 23:17:27,036 - netcdf - ERROR - Excepcion: tipo <type 'exceptions.IndexError'>; 
tuple index out of range
Traceback (most recent call last):
  File "netcdf.py", line 149, in <module>
    print "TIEMPO: {} índice {}".format(row[0],indice_time[0])
IndexError: tuple index out of range
