2014-06-20 10:30:47,082 - netcdf - ERROR - ERROR: lock file already exists

2014-06-20 10:31:10,180 - netcdf - ERROR - Database Error: tipo <class 'psycopg2.ProgrammingError'>; código: 42601 
error de sintaxis en o cerca de «)»
LINE 1: ...time_shipcargo_daily WHERE date='2014-06-01'::date LIMIT 2);
                                                                     ^
Traceback (most recent call last):
  File "netcdf.py", line 78, in <module>
    cursor_con.execute(sentencia)
ProgrammingError: error de sintaxis en o cerca de «)»
LINE 1: ...time_shipcargo_daily WHERE date='2014-06-01'::date LIMIT 2);
                                                                     ^

2014-06-20 10:38:34,506 - netcdf - ERROR - Database Error: tipo <class 'psycopg2.ProgrammingError'>; código: 42601 
error de sintaxis en o cerca de «)»
LINE 1: ...time_shipcargo_daily WHERE date='2014-06-01'::date LIMIT 2);
                                                                     ^
Traceback (most recent call last):
  File "netcdf.py", line 78, in <module>
    cursor_con.execute(sentencia)
ProgrammingError: error de sintaxis en o cerca de «)»
LINE 1: ...time_shipcargo_daily WHERE date='2014-06-01'::date LIMIT 2);
                                                                     ^

2014-06-20 10:48:48,546 - netcdf - ERROR - ERROR: lock file already exists

2014-06-20 10:53:55,385 - netcdf - ERROR - ERROR: lock file already exists

2014-06-20 10:54:01,081 - netcdf - ERROR - Database Error: tipo <class 'psycopg2.ProgrammingError'>; código: 42601 
error de sintaxis en o cerca de «)»
LINE 1: ...time_shipcargo_daily WHERE date='2014-06-01'::date LIMIT 2);
                                                                     ^
Traceback (most recent call last):
  File "netcdf.py", line 94, in <module>
    cursor_con.execute(sentencia)
ProgrammingError: error de sintaxis en o cerca de «)»
LINE 1: ...time_shipcargo_daily WHERE date='2014-06-01'::date LIMIT 2);
                                                                     ^

2014-06-21 18:19:11,451 - netcdf - ERROR - Database Error: tipo <class 'psycopg2.ProgrammingError'>; código: 42601 
error de sintaxis en o cerca de «)»
LINE 1: ...time_shipcargo_daily WHERE date='2014-06-01'::date LIMIT 2);
                                                                     ^
Traceback (most recent call last):
  File "netcdf.py", line 94, in <module>
    cursor_con.execute(sentencia)
ProgrammingError: error de sintaxis en o cerca de «)»
LINE 1: ...time_shipcargo_daily WHERE date='2014-06-01'::date LIMIT 2);
                                                                     ^

2014-06-21 18:20:02,798 - netcdf - ERROR - Database Error: tipo <class 'psycopg2.ProgrammingError'>; código: 42601 
error de sintaxis en o cerca de «)»
LINE 1: ...time_shipcargo_daily WHERE date='2014-06-01'::date LIMIT 2);
                                                                     ^
Traceback (most recent call last):
  File "netcdf.py", line 96, in <module>
    cursor_con.execute(sentencia)
ProgrammingError: error de sintaxis en o cerca de «)»
LINE 1: ...time_shipcargo_daily WHERE date='2014-06-01'::date LIMIT 2);
                                                                     ^

2014-06-21 18:21:01,024 - netcdf - ERROR - Database Error: tipo <class 'psycopg2.ProgrammingError'>; código: 42601 
error de sintaxis en o cerca de «)»
LINE 1: ...time_shipcargo_daily WHERE date='2014-06-01'::date LIMIT 2);
                                                                     ^
Traceback (most recent call last):
  File "netcdf.py", line 96, in <module>
    cursor_con.execute(sentencia)
ProgrammingError: error de sintaxis en o cerca de «)»
LINE 1: ...time_shipcargo_daily WHERE date='2014-06-01'::date LIMIT 2);
                                                                     ^

2014-06-21 18:24:36,710 - netcdf - ERROR - Database Error: tipo <class 'psycopg2.ProgrammingError'>; código: 42P01 
falta una entrada para la tabla «marine_traffic» en la cláusula FROM
LINE 1: SELECT marine_traffic.marine_traffic.grid_time_shipcargo_dai...
               ^
Traceback (most recent call last):
  File "netcdf.py", line 96, in <module>
    cursor_con.execute(sentencia)
ProgrammingError: falta una entrada para la tabla «marine_traffic» en la cláusula FROM
LINE 1: SELECT marine_traffic.marine_traffic.grid_time_shipcargo_dai...
               ^

2014-06-21 18:25:29,986 - netcdf - ERROR - Database Error: tipo <class 'psycopg2.NotSupportedError'>; código: 0A000 
no están implementadas las referencias entre bases de datos: «marine_traffic.marine_traffic.grid_time_shipcargo_daily»
LINE 1: SELECT * FROM marine_traffic.marine_traffic.grid_time_shipca...
                      ^
Traceback (most recent call last):
  File "netcdf.py", line 96, in <module>
    cursor_con.execute(sentencia)
NotSupportedError: no están implementadas las referencias entre bases de datos: «marine_traffic.marine_traffic.grid_time_shipcargo_daily»
LINE 1: SELECT * FROM marine_traffic.marine_traffic.grid_time_shipca...
                      ^

2014-06-21 18:30:17,755 - netcdf - ERROR - ERROR: lock file already exists

2014-06-21 18:40:35,096 - netcdf - ERROR - ERROR: lock file already exists

2014-06-21 18:55:15,297 - netcdf - ERROR - ERROR: lock file already exists

2014-06-21 19:12:55,419 - netcdf - ERROR - ERROR: lock file already exists

2014-06-21 19:16:14,076 - netcdf - ERROR - ERROR: lock file already exists

2014-06-21 19:23:49,310 - netcdf - ERROR - Excepcion: tipo <type 'exceptions.NameError'>; 
name 'np' is not defined
Traceback (most recent call last):
  File "netcdf.py", line 97, in <module>
    AA = np.asarray(cursor_con.fetchall())
NameError: name 'np' is not defined
2014-06-21 19:24:48,410 - netcdf - ERROR - Excepcion: tipo <type 'exceptions.NameError'>; 
name 'asarray' is not defined
Traceback (most recent call last):
  File "netcdf.py", line 97, in <module>
    AA = asarray(cursor_con.fetchall())
NameError: name 'asarray' is not defined
2014-06-21 19:26:01,295 - netcdf - ERROR - Excepcion: tipo <type 'exceptions.NameError'>; 
name 'np' is not defined
Traceback (most recent call last):
  File "netcdf.py", line 116, in <module>
    A = np.asarray(results)
NameError: name 'np' is not defined
2014-06-21 19:27:11,161 - netcdf - ERROR - Excepcion: tipo <type 'exceptions.NameError'>; 
name 'np' is not defined
Traceback (most recent call last):
  File "netcdf.py", line 116, in <module>
    A = np.asarray(results)
NameError: name 'np' is not defined
2014-06-21 19:28:00,311 - netcdf - ERROR - Excepcion: tipo <type 'exceptions.ValueError'>; 
field named f0 not found.
Traceback (most recent call last):
  File "netcdf.py", line 118, in <module>
    results_c1 = AA['f0']
ValueError: field named f0 not found.
2014-06-23 18:54:52,503 - netcdf - ERROR - Excepcion: tipo <type 'exceptions.TypeError'>; 
float() argument must be a string or a number
Traceback (most recent call last):
  File "netcdf.py", line 97, in <module>
    result = numpy.fromiter((tuple (row) for row in cursor_con), dtype=[('date',float), ('ship_cargo',int),('time_sec',float)])
TypeError: float() argument must be a string or a number
2014-06-23 18:58:32,934 - netcdf - ERROR - Excepcion: tipo <type 'exceptions.TypeError'>; 
data type not understood
Traceback (most recent call last):
  File "netcdf.py", line 98, in <module>
    result = numpy.fromiter((tuple (row) for row in cursor_con), dtype=('f8','f8','f8'))
TypeError: data type not understood
2014-06-23 19:00:13,628 - netcdf - ERROR - Excepcion: tipo <type 'exceptions.TypeError'>; 
data type not understood
Traceback (most recent call last):
  File "netcdf.py", line 98, in <module>
    result = numpy.fromiter((tuple (row) for row in cursor_con), dtype=(numpy.float,numpy.float,numpy.float))
TypeError: data type not understood
2014-06-23 19:01:10,849 - netcdf - ERROR - Excepcion: tipo <type 'exceptions.TypeError'>; 
data type not understood
Traceback (most recent call last):
  File "netcdf.py", line 98, in <module>
    result = numpy.fromiter((tuple (row) for row in cursor_con), dtype=(float,float,float))
TypeError: data type not understood
2014-06-23 19:01:48,183 - netcdf - ERROR - Excepcion: tipo <type 'exceptions.TypeError'>; 
Required argument 'dtype' (pos 2) not found
Traceback (most recent call last):
  File "netcdf.py", line 98, in <module>
    result = numpy.fromiter((tuple (row) for row in cursor_con))
TypeError: Required argument 'dtype' (pos 2) not found
2014-06-23 19:12:01,671 - netcdf - ERROR - Excepcion: tipo <type 'exceptions.TypeError'>; 
float() argument must be a string or a number
Traceback (most recent call last):
  File "netcdf.py", line 98, in <module>
    result = numpy.fromiter((tuple (row) for row in cursor_con), dtype='f8,f8,f8')
TypeError: float() argument must be a string or a number
2014-06-24 06:52:28,954 - netcdf - ERROR - Excepcion: tipo <type 'exceptions.TypeError'>; 
float() argument must be a string or a number
Traceback (most recent call last):
  File "netcdf.py", line 98, in <module>
    result = numpy.fromiter((tuple (row) for row in cursor_con), dtype='f8,f8,f8')
TypeError: float() argument must be a string or a number
2014-06-24 06:53:57,538 - netcdf - ERROR - Excepcion: tipo <type 'exceptions.TypeError'>; 
float() argument must be a string or a number
Traceback (most recent call last):
  File "netcdf.py", line 99, in <module>
    result = numpy.fromiter((tuple (row) for row in cursor_con), dtype='f8,f8,f8')
TypeError: float() argument must be a string or a number
2014-06-24 06:55:28,104 - netcdf - ERROR - Excepcion: tipo <type 'exceptions.TypeError'>; 
long() argument must be a string or a number, not 'datetime.date'
Traceback (most recent call last):
  File "netcdf.py", line 106, in <module>
    arrayi = numpy.fromiter(resultis_as_list, dtype=numpy.int32)
TypeError: long() argument must be a string or a number, not 'datetime.date'
2014-06-24 07:02:46,709 - netcdf - ERROR - Excepcion: tipo <type 'exceptions.TypeError'>; 
data type not understood
Traceback (most recent call last):
  File "netcdf.py", line 106, in <module>
    arrayi = numpy.fromiter(resultis_as_list, dtype=(numpy.long, numpy.int, numpy.float))
TypeError: data type not understood
2014-06-24 07:09:25,314 - netcdf - ERROR - Excepcion: tipo <type 'exceptions.TypeError'>; 
data type not understood
Traceback (most recent call last):
  File "netcdf.py", line 106, in <module>
    arrayi = numpy.fromiter(resultis_as_list, dtype=(numpy.float, numpy.float, numpy.float))
TypeError: data type not understood
2014-06-24 07:12:57,201 - netcdf - ERROR - Excepcion: tipo <type 'exceptions.NameError'>; 
name 'float64' is not defined
Traceback (most recent call last):
  File "netcdf.py", line 106, in <module>
    arrayi = numpy.fromiter(resultis_as_list, dtype=(float64, float64, float64))
NameError: name 'float64' is not defined
2014-06-24 07:15:36,334 - netcdf - ERROR - Excepcion: tipo <type 'exceptions.TypeError'>; 
data type not understood
Traceback (most recent call last):
  File "netcdf.py", line 106, in <module>
    arrayi = numpy.fromiter(resultis_as_list, dtype=(numpy.float64, numpy.float64, numpy.float64))
TypeError: data type not understood
2014-06-24 07:16:28,473 - netcdf - ERROR - Excepcion: tipo <type 'exceptions.TypeError'>; 
data type not understood
Traceback (most recent call last):
  File "netcdf.py", line 106, in <module>
    arrayi = numpy.fromiter(resultis_as_list, dtype='numpy.float64, numpy.float64, numpy.float64')
TypeError: data type not understood
2014-06-24 07:19:36,414 - netcdf - ERROR - Excepcion: tipo <type 'exceptions.TypeError'>; 
expected a readable buffer object
Traceback (most recent call last):
  File "netcdf.py", line 106, in <module>
    arrayi = numpy.fromiter(resultis_as_list, dtype="f8,f8,f8")
TypeError: expected a readable buffer object
2014-06-24 07:21:19,919 - netcdf - ERROR - Excepcion: tipo <type 'exceptions.TypeError'>; 
expected a readable buffer object
Traceback (most recent call last):
  File "netcdf.py", line 106, in <module>
    arrayi = numpy.fromiter(resultis_as_list, dtype="f8,f8,f8")
TypeError: expected a readable buffer object
2014-06-24 07:49:23,401 - netcdf - ERROR - Excepcion: tipo <type 'exceptions.NameError'>; 
name 'result' is not defined
Traceback (most recent call last):
  File "netcdf.py", line 111, in <module>
    print "result: {}".format(result)
NameError: name 'result' is not defined
2014-06-24 07:51:12,706 - netcdf - ERROR - Excepcion: tipo <type 'exceptions.NameError'>; 
name 'result' is not defined
Traceback (most recent call last):
  File "netcdf.py", line 111, in <module>
    print "result: {}".format(result)
NameError: name 'result' is not defined
2014-06-24 07:52:54,335 - netcdf - ERROR - Excepcion: tipo <type 'exceptions.TypeError'>; 
float() argument must be a string or a number
Traceback (most recent call last):
  File "netcdf.py", line 110, in <module>
    data1 = numpy.array(data[:,0],dtype="Float64")
TypeError: float() argument must be a string or a number
2014-06-24 07:54:01,815 - netcdf - ERROR - Excepcion: tipo <type 'exceptions.TypeError'>; 
float() argument must be a string or a number
Traceback (most recent call last):
  File "netcdf.py", line 110, in <module>
    data1 = numpy.array(data[:,0],dtype='f8')
TypeError: float() argument must be a string or a number
2014-06-24 07:55:03,281 - netcdf - ERROR - Excepcion: tipo <type 'exceptions.TypeError'>; 
float() argument must be a string or a number
Traceback (most recent call last):
  File "netcdf.py", line 110, in <module>
    data1 = numpy.array(data[0],dtype='f8')
TypeError: float() argument must be a string or a number
2014-06-24 08:38:45,825 - netcdf - ERROR - Excepcion: tipo <type 'exceptions.TypeError'>; 
float() argument must be a string or a number
Traceback (most recent call last):
  File "netcdf.py", line 110, in <module>
    data1 = numpy.array(data[0],dtype='f8')
TypeError: float() argument must be a string or a number
2014-06-24 08:40:40,946 - netcdf - ERROR - Excepcion: tipo <type 'exceptions.TypeError'>; 
float() argument must be a string or a number
Traceback (most recent call last):
  File "netcdf.py", line 110, in <module>
    data1 = numpy.array(data[:,0],dtype='f8')
TypeError: float() argument must be a string or a number
2014-06-24 08:41:23,766 - netcdf - ERROR - Excepcion: tipo <type 'exceptions.NameError'>; 
name 'data1' is not defined
Traceback (most recent call last):
  File "netcdf.py", line 112, in <module>
    print "result: {}".format(data1)
NameError: name 'data1' is not defined
2014-06-24 08:42:25,686 - netcdf - ERROR - Excepcion: tipo <type 'exceptions.NameError'>; 
name 'result' is not defined
Traceback (most recent call last):
  File "netcdf.py", line 116, in <module>
    results_c1 = result['f0']
NameError: name 'result' is not defined
